Traceback (most recent call last):
  File "/home/s0558366/.local/lib/python3.7/site-packages/lockfile/pidlockfile.py", line 77, in acquire
    write_pid_to_pidfile(self.path)
  File "/home/s0558366/.local/lib/python3.7/site-packages/lockfile/pidlockfile.py", line 161, in write_pid_to_pidfile
    pidfile_fd = os.open(pidfile_path, open_flags, open_mode)
FileNotFoundError: [Errno 2] No such file or directory: './airlfow/airflow-webserver-monitor.pid'

During handling of the above exception, another exception occurred:

Traceback (most recent call last):
  File "/home/s0558366/.local/bin/airflow", line 37, in <module>
    args.func(args)
  File "/home/s0558366/.local/lib/python3.7/site-packages/airflow/utils/cli.py", line 76, in wrapper
    return f(*args, **kwargs)
  File "/home/s0558366/.local/lib/python3.7/site-packages/airflow/bin/cli.py", line 1157, in webserver
    with ctx:
  File "/home/s0558366/.local/lib/python3.7/site-packages/daemon/daemon.py", line 389, in __enter__
    self.open()
  File "/home/s0558366/.local/lib/python3.7/site-packages/daemon/daemon.py", line 381, in open
    self.pidfile.__enter__()
  File "/home/s0558366/.local/lib/python3.7/site-packages/lockfile/__init__.py", line 197, in __enter__
    self.acquire()
  File "/home/s0558366/.local/lib/python3.7/site-packages/daemon/pidfile.py", line 57, in acquire
    super(TimeoutPIDLockFile, self).acquire(timeout, *args, **kwargs)
  File "/home/s0558366/.local/lib/python3.7/site-packages/lockfile/pidlockfile.py", line 91, in acquire
    raise LockFailed("failed to create %s" % self.path)
lockfile.LockFailed: failed to create ./airlfow/airflow-webserver-monitor.pid
